[
  {
    "number": 14,
    "title": "Error running ranking and trading client : TypeError: model_schema() got an unexpected keyword argument 'generic_origin'",
    "created_at": "2024-12-05T16:37:43Z",
    "closed_at": "2024-12-05T17:00:57Z",
    "labels": [],
    "url": "https://github.com/yeonholee50/AmpyFin/issues/14",
    "body": "Getting an error when running ranking_client and trading_client. I am on Python 3.11.10.\r\n\r\n>python ranking_client.py\r\nTraceback (most recent call last):\r\n  File \"\\AmpyFin\\ranking_client.py\", line 12, in <module>\r\n    from alpaca.trading.client import TradingClient\r\n  File \"\\anaconda3\\envs\\ampyfin\\Lib\\site-packages\\alpaca\\trading\\__init__.py\", line 1, in <module>\r\n    from alpaca.trading.client import *\r\n  File \"\\anaconda3\\envs\\ampyfin\\Lib\\site-packages\\alpaca\\trading\\client.py\", line 5, in <module>\r\n    from alpaca.common import RawData\r\n  File \"\\anaconda3\\envs\\ampyfin\\Lib\\site-packages\\alpaca\\common\\__init__.py\", line 1, in <module>\r\n    from alpaca.common.models import *\r\n  File \"\\anaconda3\\envs\\ampyfin\\Lib\\site-packages\\alpaca\\common\\models.py\", line 6, in <module>\r\n    class ValidateBaseModel(BaseModel, validate_assignment=True):\r\n  File \"\\anaconda3\\envs\\ampyfin\\Lib\\site-packages\\pydantic\\_internal\\_model_construction.py\", line 226, in __new__\r\n    complete_model_class(\r\n  File \"\\anaconda3\\envs\\ampyfin\\Lib\\site-packages\\pydantic\\_internal\\_model_construction.py\", line 658, in complete_model_class\r\n    schema = cls.__get_pydantic_core_schema__(cls, handler)\r\n             ^^^^^^^^^^^^^^^^^^^^^^^^^^^^^^^^^^^^^^^^^^^^^^\r\n  File \"\\anaconda3\\envs\\ampyfin\\Lib\\site-packages\\pydantic\\main.py\", line 702, in __get_pydantic_core_schema__\r\n    return handler(source)\r\n           ^^^^^^^^^^^^^^^\r\n  File \"\\anaconda3\\envs\\ampyfin\\Lib\\site-packages\\pydantic\\_internal\\_schema_generation_shared.py\", line 84, in __call__       \r\n    schema = self._handler(source_type)\r\n             ^^^^^^^^^^^^^^^^^^^^^^^^^^\r\n  File \"\\anaconda3\\envs\\ampyfin\\Lib\\site-packages\\pydantic\\_internal\\_generate_schema.py\", line 612, in generate_schema        \r\n    schema = self._generate_schema_inner(obj)\r\n             ^^^^^^^^^^^^^^^^^^^^^^^^^^^^^^^^\r\n  File \"\\anaconda3\\envs\\ampyfin\\Lib\\site-packages\\pydantic\\_internal\\_generate_schema.py\", line 881, in _generate_schema_inner \r\n    return self._model_schema(obj)\r\n           ^^^^^^^^^^^^^^^^^^^^^^^\r\n  File \"\\anaconda3\\envs\\ampyfin\\Lib\\site-packages\\pydantic\\_internal\\_generate_schema.py\", line 707, in _model_schema\r\n    model_schema = core_schema.model_schema(\r\n                   ^^^^^^^^^^^^^^^^^^^^^^^^^\r\nTypeError: model_schema() got an unexpected keyword argument 'generic_origin'",
    "comments_url": "https://api.github.com/repos/yeonholee50/AmpyFin/issues/14/comments",
    "author": "sukhcs",
    "comments": [
      {
        "user": "yeonholee50",
        "created_at": "2024-12-05T16:55:17Z",
        "body": "There seems to be a compatability issue with the current version of Python with pydantic. You may need to downgrade your Python version and then retry. I will look into this seperately"
      }
    ]
  }
]