[
  {
    "number": 325,
    "title": "Stuck in loop when trying to build docker container",
    "created_at": "2025-02-04T08:33:18Z",
    "closed_at": "2025-02-08T09:55:01Z",
    "labels": [],
    "url": "https://github.com/cocktailpeanut/fluxgym/issues/325",
    "body": "Following the install guide for docker, when I attempt to run `docker compose up -d --build` running `docker ps` showed the container was stuck in a boot loop. Removing the `-d` from the build I received this error\n\n` ✔ Network fluxgym_default  Created                                                                                                                     0.1s\n ✔ Container fluxgym        Created                                                                                                                     0.1s\nAttaching to fluxgym\n\nfluxgym  | Traceback (most recent call last):\n\nfluxgym  |   File \"/usr/local/lib/python3.10/dist-packages/diffusers/utils/import_utils.py\", line 943, in _get_module\n\nfluxgym  |     return importlib.import_module(\".\" + module_name, self.__name__)\n\nfluxgym  |   File \"/usr/lib/python3.10/importlib/__init__.py\", line 126, in import_module\n\nfluxgym  |     return _bootstrap._gcd_import(name[level:], package, level)\n\nfluxgym  |   File \"<frozen importlib._bootstrap>\", line 1050, in _gcd_import\n\nfluxgym  |   File \"<frozen importlib._bootstrap>\", line 1027, in _find_and_load\n\nfluxgym  |   File \"<frozen importlib._bootstrap>\", line 1006, in _find_and_load_unlocked\n\nfluxgym  |   File \"<frozen importlib._bootstrap>\", line 688, in _load_unlocked\n\nfluxgym  |   File \"<frozen importlib._bootstrap_external>\", line 883, in exec_module\n\nfluxgym  |   File \"<frozen importlib._bootstrap>\", line 241, in _call_with_frames_removed\n\nfluxgym  |   File \"/usr/local/lib/python3.10/dist-packages/diffusers/loaders/single_file.py\", line 24, in <module>\n\nfluxgym  |     from .single_file_utils import (\n\nfluxgym  |   File \"/usr/local/lib/python3.10/dist-packages/diffusers/loaders/single_file_utils.py\", line 28, in <module>\n\nfluxgym  |     from ..models.modeling_utils import load_state_dict\n\nfluxgym  |   File \"/usr/local/lib/python3.10/dist-packages/diffusers/models/modeling_utils.py\", line 37, in <module>\n\nfluxgym  |     from ..quantizers import DiffusersAutoQuantizer, DiffusersQuantizer\n\nfluxgym  |   File \"/usr/local/lib/python3.10/dist-packages/diffusers/quantizers/__init__.py\", line 15, in <module>\n\nfluxgym  |     from .auto import DiffusersAutoQuantizer\n\nfluxgym  |   File \"/usr/local/lib/python3.10/dist-packages/diffusers/quantizers/auto.py\", line 22, in <module>\n\nfluxgym  |     from .bitsandbytes import BnB4BitDiffusersQuantizer, BnB8BitDiffusersQuantizer\n\nfluxgym  |   File \"/usr/local/lib/python3.10/dist-packages/diffusers/quantizers/bitsandbytes/__init__.py\", line 2, in <module>\n\nfluxgym  |     from .utils import dequantize_and_replace, dequantize_bnb_weight, replace_with_bnb_linear\n\nfluxgym  |   File \"/usr/local/lib/python3.10/dist-packages/diffusers/quantizers/bitsandbytes/utils.py\", line 32, in <module>\n\nfluxgym  |     import bitsandbytes as bnb\n\nfluxgym  |   File \"/usr/local/lib/python3.10/dist-packages/bitsandbytes/__init__.py\", line 15, in <module>\n\nfluxgym  |     from .nn import modules\n\nfluxgym  |   File \"/usr/local/lib/python3.10/dist-packages/bitsandbytes/nn/__init__.py\", line 21, in <module>\n\nfluxgym  |     from .triton_based_modules import (\n\nfluxgym  |   File \"/usr/local/lib/python3.10/dist-packages/bitsandbytes/nn/triton_based_modules.py\", line 7, in <module>\n\nfluxgym  |     from bitsandbytes.triton.int8_matmul_mixed_dequantize import (\n\nfluxgym  |   File \"/usr/local/lib/python3.10/dist-packages/bitsandbytes/triton/int8_matmul_mixed_dequantize.py\", line 12, in <module>\n\nfluxgym  |     from triton.ops.matmul_perf_model import early_config_prune, estimate_matmul_time\n\nfluxgym  | ModuleNotFoundError: No module named 'triton.ops'\n`\n\nI inserted `triton` into the list of packages to be installed by `pip` in the Dockerfile. I ran `docker build --no-cache` to rebuild everything, and saw triton being installed in one of the steps. However I still receive the exact same error message, and I can't seem to find any answers on Google how to fix this. Any help would be appreciated.",
    "comments_url": "https://api.github.com/repos/cocktailpeanut/fluxgym/issues/325/comments",
    "author": "gavanpang",
    "comments": [
      {
        "user": "aaron-pak",
        "created_at": "2025-02-05T23:36:38Z",
        "body": "Can confirm having the same issue"
      },
      {
        "user": "namila007",
        "created_at": "2025-02-07T19:35:24Z",
        "body": "having the same issue"
      },
      {
        "user": "namila007",
        "created_at": "2025-02-07T20:32:17Z",
        "body": "fixed the issue by adding this after line 32 on DockerFile\n  `RUN pip install --upgrade --force-reinstall triton==2.1.0`"
      },
      {
        "user": "echostorm",
        "created_at": "2025-02-08T00:18:04Z",
        "body": "thanks was facing same issue, works after adding triton."
      },
      {
        "user": "gavanpang",
        "created_at": "2025-02-08T09:55:01Z",
        "body": "Thank you for the solution, it's working now!"
      }
    ]
  },
  {
    "number": 231,
    "title": "Runner: <LogsViewRunner nb_logs=56 exit_code=1>",
    "created_at": "2024-11-01T14:25:10Z",
    "closed_at": "2024-11-07T00:17:36Z",
    "labels": [],
    "url": "https://github.com/cocktailpeanut/fluxgym/issues/231",
    "body": "2024-11-01 17:58:06] [INFO] To avoid this warning pass in values for each of the problematic parameters or run accelerate config.\r\n[2024-11-01 17:58:10] [INFO] 2024-11-01 17:58:10 INFO     highvram is enabled /           train_util.py:4106\r\n[2024-11-01 17:58:10] [INFO] highvramが有効です\r\n[2024-11-01 17:58:10] [INFO] WARNING  cache_latents_to_disk is        train_util.py:4123\r\n[2024-11-01 17:58:10] [INFO] enabled, so cache_latents is\r\n[2024-11-01 17:58:10] [INFO] also enabled /\r\n[2024-11-01 17:58:10] [INFO] cache_latents_to_diskが有効なた\r\n[2024-11-01 17:58:10] [INFO] め、cache_latentsを有効にします\r\n[2024-11-01 17:58:10] [INFO] 2024-11-01 17:58:10 INFO     Checking the state dict:          flux_utils.py:62\r\n[2024-11-01 17:58:10] [INFO] Diffusers or BFL, dev or schnell\r\n[2024-11-01 17:58:10] [INFO] INFO     t5xxl_max_token_length:  flux_train_network.py:152\r\n[2024-11-01 17:58:10] [INFO] 512\r\n[2024-11-01 17:58:10] [INFO] Traceback (most recent call last):\r\n[2024-11-01 17:58:10] [INFO] File \"E:\\fluxgym\\sd-scripts\\flux_train_network.py\", line 564, in <module>\r\n[2024-11-01 17:58:10] [INFO] trainer.train(args)\r\n[2024-11-01 17:58:10] [INFO] File \"E:\\fluxgym\\sd-scripts\\train_network.py\", line 292, in train\r\n[2024-11-01 17:58:10] [INFO] tokenize_strategy = self.get_tokenize_strategy(args)\r\n[2024-11-01 17:58:10] [INFO] File \"E:\\fluxgym\\sd-scripts\\flux_train_network.py\", line 153, in get_tokenize_strategy\r\n[2024-11-01 17:58:10] [INFO] return strategy_flux.FluxTokenizeStrategy(t5xxl_max_token_length, args.tokenizer_cache_dir)\r\n[2024-11-01 17:58:10] [INFO] File \"E:\\fluxgym\\sd-scripts\\library\\strategy_flux.py\", line 26, in __init__\r\n[2024-11-01 17:58:10] [INFO] self.clip_l = self._load_tokenizer(CLIPTokenizer, CLIP_L_TOKENIZER_ID, tokenizer_cache_dir=tokenizer_cache_dir)\r\n[2024-11-01 17:58:10] [INFO] File \"E:\\fluxgym\\sd-scripts\\library\\strategy_base.py\", line 65, in _load_tokenizer\r\n[2024-11-01 17:58:10] [INFO] tokenizer = model_class.from_pretrained(model_id, subfolder=subfolder)\r\n[2024-11-01 17:58:10] [INFO] File \"E:\\fluxgym\\env\\lib\\site-packages\\transformers\\tokenization_utils_base.py\", line 2210, in from_pretrained\r\n[2024-11-01 17:58:10] [INFO] tokenizer_config = json.load(reader)\r\n[2024-11-01 17:58:10] [INFO] File \"C:\\Users\\Administrator\\AppData\\Local\\Programs\\Python\\Python310\\lib\\json\\__init__.py\", line 293, in load\r\n[2024-11-01 17:58:10] [INFO] return loads(fp.read(),\r\n[2024-11-01 17:58:10] [INFO] File \"C:\\Users\\Administrator\\AppData\\Local\\Programs\\Python\\Python310\\lib\\json\\__init__.py\", line 346, in loads\r\n[2024-11-01 17:58:10] [INFO] return _default_decoder.decode(s)\r\n[2024-11-01 17:58:10] [INFO] File \"C:\\Users\\Administrator\\AppData\\Local\\Programs\\Python\\Python310\\lib\\json\\decoder.py\", line 337, in decode\r\n[2024-11-01 17:58:10] [INFO] obj, end = self.raw_decode(s, idx=_w(s, 0).end())\r\n[2024-11-01 17:58:10] [INFO] File \"C:\\Users\\Administrator\\AppData\\Local\\Programs\\Python\\Python310\\lib\\json\\decoder.py\", line 355, in raw_decode\r\n[2024-11-01 17:58:10] [INFO] raise JSONDecodeError(\"Expecting value\", s, err.value) from None\r\n[2024-11-01 17:58:10] [INFO] json.decoder.JSONDecodeError: Expecting value: line 1 column 1 (char 0)\r\n[2024-11-01 17:58:11] [INFO] Traceback (most recent call last):\r\n[2024-11-01 17:58:11] [INFO] File \"C:\\Users\\Administrator\\AppData\\Local\\Programs\\Python\\Python310\\lib\\runpy.py\", line 196, in _run_module_as_main\r\n[2024-11-01 17:58:11] [INFO] return _run_code(code, main_globals, None,\r\n[2024-11-01 17:58:11] [INFO] File \"C:\\Users\\Administrator\\AppData\\Local\\Programs\\Python\\Python310\\lib\\runpy.py\", line 86, in _run_code\r\n[2024-11-01 17:58:11] [INFO] exec(code, run_globals)\r\n[2024-11-01 17:58:11] [INFO] File \"E:\\fluxgym\\env\\Scripts\\accelerate.exe\\__main__.py\", line 7, in <module>\r\n[2024-11-01 17:58:11] [INFO] sys.exit(main())\r\n[2024-11-01 17:58:11] [INFO] File \"E:\\fluxgym\\env\\lib\\site-packages\\accelerate\\commands\\accelerate_cli.py\", line 48, in main\r\n[2024-11-01 17:58:11] [INFO] args.func(args)\r\n[2024-11-01 17:58:11] [INFO] File \"E:\\fluxgym\\env\\lib\\site-packages\\accelerate\\commands\\launch.py\", line 1106, in launch_command\r\n[2024-11-01 17:58:11] [INFO] simple_launcher(args)\r\n[2024-11-01 17:58:11] [INFO] File \"E:\\fluxgym\\env\\lib\\site-packages\\accelerate\\commands\\launch.py\", line 704, in simple_launcher\r\n[2024-11-01 17:58:11] [INFO] raise subprocess.CalledProcessError(returncode=process.returncode, cmd=cmd)\r\n[2024-11-01 17:58:11] [INFO] subprocess.CalledProcessError: Command '['E:\\\\fluxgym\\\\env\\\\Scripts\\\\python.exe', 'sd-scripts/flux_train_network.py', '--pretrained_model_name_or_path', 'E:\\\\fluxgym\\\\models\\\\unet\\\\flux1-dev.sft', '--clip_l', 'E:\\\\fluxgym\\\\models\\\\clip\\\\clip_l.safetensors', '--t5xxl', 'E:\\\\fluxgym\\\\models\\\\clip\\\\t5xxl_fp16.safetensors', '--ae', 'E:\\\\fluxgym\\\\models\\\\vae\\\\ae.sft', '--cache_latents_to_disk', '--save_model_as', 'safetensors', '--sdpa', '--persistent_data_loader_workers', '--max_data_loader_n_workers', '2', '--seed', '42', '--gradient_checkpointing', '--mixed_precision', 'bf16', '--save_precision', 'bf16', '--network_module', 'networks.lora_flux', '--network_dim', '4', '--optimizer_type', 'adafactor', '--optimizer_args', 'relative_step=False', 'scale_parameter=False', 'warmup_init=False', '--lr_scheduler', 'constant_with_warmup', '--max_grad_norm', '0.0', '--learning_rate', '8e-4', '--cache_text_encoder_outputs', '--cache_text_encoder_outputs_to_disk', '--fp8_base', '--highvram', '--max_train_epochs', '16', '--save_every_n_epochs', '4', '--dataset_config', 'E:\\\\fluxgym\\\\outputs\\\\xb-lora\\\\dataset.toml', '--output_dir', 'E:\\\\fluxgym\\\\outputs\\\\xb-lora', '--output_name', 'xb-lora', '--timestep_sampling', 'shift', '--discrete_flow_shift', '3.1582', '--model_prediction_type', 'raw', '--guidance_scale', '1', '--loss_type', 'l2']' returned non-zero exit status 1.\r\n[2024-11-01 17:58:11] [ERROR] Command exited with code 1\r\n[2024-11-01 17:58:11] [INFO] Runner: <LogsViewRunner nb_logs=56 exit_code=1>",
    "comments_url": "https://api.github.com/repos/cocktailpeanut/fluxgym/issues/231/comments",
    "author": "lestersssss",
    "comments": [
      {
        "user": "Hiddengenie",
        "created_at": "2024-11-02T11:41:06Z",
        "body": "Check whether your ae.sft (in the vae folder) is complete and uncorrupted. If it is then try uploading an older version - I uploaded a version from September and that solved the isse. "
      },
      {
        "user": "alexnikospb",
        "created_at": "2024-11-06T18:25:03Z",
        "body": "I have the same problem:  Runner: LogsViewRunner nb_logs=38 exit_code=1"
      },
      {
        "user": "lestersssss",
        "created_at": "2024-11-07T00:17:25Z",
        "body": "> Check whether your ae.sft (in the vae folder) is complete and uncorrupted. If it is then try uploading an older version - I uploaded a version from September and that solved the isse.\r\n\r\nthank you!"
      },
      {
        "user": "Samchris01",
        "created_at": "2024-11-13T03:04:53Z",
        "body": "> Check whether your ae.sft (in the vae folder) is complete and uncorrupted. If it is then try uploading an older version - I uploaded\r\n\r\nHow to download\r\n"
      },
      {
        "user": "love9678",
        "created_at": "2025-01-06T08:57:21Z",
        "body": "How to download"
      },
      {
        "user": "TijmenJansen0",
        "created_at": "2025-01-26T17:50:58Z",
        "body": "I had the same error after downloading and using the UI locally. \nBug can be fixed by running (in terminal/bash)\nexport PATH=\"/PATH_TO_YOUR_ENVIRONMENT/bin:$PATH\"\n\nbefore running \npython app.py\n"
      }
    ]
  },
  {
    "number": 156,
    "title": "torch.cpu.amp.autocast(args...)` is deprecated. Please use `torch.amp.autocast('cpu', args...)` instead.",
    "created_at": "2024-10-01T01:45:47Z",
    "closed_at": "2024-10-01T03:32:37Z",
    "labels": [],
    "url": "https://github.com/cocktailpeanut/fluxgym/issues/156",
    "body": "Was working fine yesterday. Now I can't seem to make it work\r\n\r\n\\checkpoint.py:1399: FutureWarning: `torch.cpu.amp.autocast(args...)` is deprecated. Please use `torch.amp.autocast('cpu', args...)` instead.",
    "comments_url": "https://api.github.com/repos/cocktailpeanut/fluxgym/issues/156/comments",
    "author": "Iamausername1958",
    "comments": [
      {
        "user": "restofworld",
        "created_at": "2024-10-01T02:20:29Z",
        "body": "same problem"
      },
      {
        "user": "Iamausername1958",
        "created_at": "2024-10-01T02:32:12Z",
        "body": "Found another thread ( I should have checked before... sorry!) with that same problem. This was cocktailpeanut's answer: \r\n\r\n\r\n\"I think this is a warning and not an error. Unless the process crashes it is still going.\r\n\r\nEven I see this warning message but the training works fine. The reason it is not updating quickly is because the script seems to only print all the updates after each epoch (instead of each step).\r\n\r\nThis means it takes quite some time before the first progress is printed on the screen. So unless the program completely crashes and you don't see any VRAM usage on your task manager, try to keep it running and see if it updates.\"\r\n\r\n\r\nWill run it overnight and update tomorrow as my GPU is indeed working in the back end! I wonder why it just stopped showing steps all of the sudden though. "
      },
      {
        "user": "baobao1712",
        "created_at": "2024-10-01T03:24:26Z",
        "body": "just let it run and it will progress to the next step, I fixed the code and it still running like this so it doesn't matter."
      },
      {
        "user": "Iamausername1958",
        "created_at": "2024-10-01T03:32:35Z",
        "body": "I can confirm that it does work! Ignore the warning if it doesn't crash. \r\n\r\nThanks everyone!"
      }
    ]
  },
  {
    "number": 149,
    "title": "[Feature request] Server Port argument",
    "created_at": "2024-09-29T23:13:22Z",
    "closed_at": "2024-10-01T16:25:18Z",
    "labels": [],
    "url": "https://github.com/cocktailpeanut/fluxgym/issues/149",
    "body": "I found and read the #80 post, and I've gotten it to work on a custom port.\r\n\r\n\r\nIt seems like it would be a nice launch argument to add to the script, as a user-friendly way to not require people to set environment variables.\r\n\r\nUsing an environment variable doesn't make sense to me since this will not be the only gradio app I'm running, which is the reason why I'm looking to change the port.\r\n\r\nI made it working like this:\r\n```\r\napp.py:\r\nif __name__ == \"__main__\":\r\n    cwd = os.path.dirname(os.path.abspath(__file__))\r\n    port = int(sys.argv[1]) if len(sys.argv) > 1 else 7860  # Default to 7860 if no port is provided\r\n    demo.launch(debug=True, show_error=True, allowed_paths=[cwd], server_port=port)\r\n\r\n\r\nIn my launch.bat:\r\n@echo off \r\nset PORT=7861\r\ncall venv\\Scripts\\activate\r\ncmd /k \"cd /d %~dp0 & call venv\\Scripts\\activate & python app.py %PORT%\"\r\n```\r\n\r\nJust in case this helps anyone else.\r\n\r\nBut I still would love to just be able to set this in a user config so I wouldn't need to update project source files.",
    "comments_url": "https://api.github.com/repos/cocktailpeanut/fluxgym/issues/149/comments",
    "author": "MNeMoNiCuZ",
    "comments": [
      {
        "user": "Semonxue",
        "created_at": "2024-09-30T15:47:13Z",
        "body": "try this:\r\n```\r\n//linux or mac\r\nexport GRADIO_SERVER_PORT=5000\r\nor\r\n//windows in cmd\r\nset GRADIO_SERVER_PORT=5000\r\n```\r\nthen run the app"
      },
      {
        "user": "MNeMoNiCuZ",
        "created_at": "2024-09-30T16:11:04Z",
        "body": "> try this:\r\n> \r\n> ```\r\n> //linux or mac\r\n> export GRADIO_SERVER_PORT=5000\r\n> or\r\n> //windows in cmd\r\n> set GRADIO_SERVER_PORT=5000\r\n> ```\r\n> \r\n> then run the app\r\n\r\nThanks for the tip.\r\nBut as mentioned in my post, I don't really want to set gradio server ports as I have other gradio apps running.\r\nI just want to be able to customize the instance of this program in a friendly way, without modifying the original code."
      },
      {
        "user": "Semonxue",
        "created_at": "2024-09-30T16:54:04Z",
        "body": "> > try this:\r\n> > ```\r\n> > //linux or mac\r\n> > export GRADIO_SERVER_PORT=5000\r\n> > or\r\n> > //windows in cmd\r\n> > set GRADIO_SERVER_PORT=5000\r\n> > ```\r\n> > \r\n> > \r\n> >     \r\n> >       \r\n> >     \r\n> > \r\n> >       \r\n> >     \r\n> > \r\n> >     \r\n> >   \r\n> > then run the app\r\n> \r\n> Thanks for the tip. But as mentioned in my post, I don't really want to set gradio server ports as I have other gradio apps running. I just want to be able to customize the instance of this program in a friendly way, without modifying the original code.\r\n\r\nThis will not edit the code. Run in CMD or terminal before run the app.py."
      },
      {
        "user": "MNeMoNiCuZ",
        "created_at": "2024-10-01T16:25:18Z",
        "body": "Ah, great! That worked as a solution for me then.\r\nCreating a .bat with this in it:\r\n\r\n@echo off\r\nset GRADIO_SERVER_PORT=5000\r\ncall venv\\Scripts\\activate\r\ncmd /k \"cd /d %~dp0 & python app.py\"\r\n\r\n\r\nThanks @Semonxue <3"
      }
    ]
  },
  {
    "number": 133,
    "title": "IndexError: list index out of range",
    "created_at": "2024-09-26T12:59:48Z",
    "closed_at": "2024-09-27T08:00:59Z",
    "labels": [],
    "url": "https://github.com/cocktailpeanut/fluxgym/issues/133",
    "body": "Encounted 2 errors：\r\n1. Fluxgym cannot create outputs/xxx/sample directory, and report dir not exist error\r\n2. After I manually created the dir, Fluxgym report the following error:\r\n\r\n  File \"K:\\ComfyUI_windows_portable\\fluxgym\\app.py\", line 625, in start_training\r\n    md = readme(base_model, lora_name, concept_sentence, sample_prompts)\r\n         ^^^^^^^^^^^^^^^^^^^^^^^^^^^^^^^^^^^^^^^^^^^^^^^^^^^^^^^^^^^^^^^\r\n  File \"K:\\ComfyUI_windows_portable\\fluxgym\\app.py\", line 73, in readme\r\n    _, _, image_path = final_sample_image_paths[i]\r\n                       ~~~~~~~~~~~~~~~~~~~~~~~~^^^\r\nIndexError: list index out of range",
    "comments_url": "https://api.github.com/repos/cocktailpeanut/fluxgym/issues/133/comments",
    "author": "deepfree2023",
    "comments": [
      {
        "user": "Shavalyoth",
        "created_at": "2024-09-27T02:54:02Z",
        "body": "I've experienced the same error."
      },
      {
        "user": "deepfree2023",
        "created_at": "2024-09-27T08:00:57Z",
        "body": "Got it. My accelerate.exe was not the the system path. "
      },
      {
        "user": "wmbassyouni",
        "created_at": "2024-09-27T21:18:54Z",
        "body": "Hi @deepfree2023 can you please provide the exact steps you took to fix it ? I have the same issue."
      },
      {
        "user": "mertayd0",
        "created_at": "2024-09-28T21:43:39Z",
        "body": "> Hi @deepfree2023 can you please provide the exact steps you took to fix it ? I have the same issue.\r\n\r\n+1"
      },
      {
        "user": "Friedrish933",
        "created_at": "2024-09-29T15:22:26Z",
        "body": "+1 @deepfree2023  @Shavalyoth "
      },
      {
        "user": "deepfree2023",
        "created_at": "2024-10-02T12:48:52Z",
        "body": "Hi, I just added my accelerate.exe path into the system path, and it worked. But not working efficiently, no partially loading into vram, the training speed was very very slow."
      }
    ]
  },
  {
    "number": 119,
    "title": "enable buckets",
    "created_at": "2024-09-21T11:48:45Z",
    "closed_at": "2024-11-02T14:30:55Z",
    "labels": [],
    "url": "https://github.com/cocktailpeanut/fluxgym/issues/119",
    "body": "enable buckets is set to false in the script, can we please get a checkbox option for this.",
    "comments_url": "https://api.github.com/repos/cocktailpeanut/fluxgym/issues/119/comments",
    "author": "zethfoxster",
    "comments": [
      {
        "user": "gohan2091",
        "created_at": "2024-10-27T16:07:09Z",
        "body": "All my images are different ratios and dimensions. Do I need to have buckets enabled? the default is off but didn't have a problem when I tried creating a LoRA a few weeks ago."
      },
      {
        "user": "zethfoxster",
        "created_at": "2024-11-02T14:30:55Z",
        "body": "its cropping the images if you dont enable buckets and have a mix...which sometimes can end up cropping off faces, or key items in the images....this issue can be closed as he since added a method to edit that directly in the webui on the right side, you can just edit it to true."
      }
    ]
  },
  {
    "number": 117,
    "title": "dose flux1-dev.safetensors supported ?",
    "created_at": "2024-09-20T15:39:15Z",
    "closed_at": "2024-09-20T15:53:01Z",
    "labels": [],
    "url": "https://github.com/cocktailpeanut/fluxgym/issues/117",
    "body": "I get this error:\r\n\r\n[2024-09-20 15:33:14] [INFO] FileNotFoundError: No such file or directory: \"/mnt/workspace/fluxgym/models/unet/flux1-dev.sft\"\r\n",
    "comments_url": "https://api.github.com/repos/cocktailpeanut/fluxgym/issues/117/comments",
    "author": "zhangjinyangnwpu",
    "comments": [
      {
        "user": "Semonxue",
        "created_at": "2024-09-24T04:47:41Z",
        "body": "@zhangjinyangnwpu Its closed means `flux1-dev.safetensors` supported?"
      }
    ]
  },
  {
    "number": 112,
    "title": "Fluxgym won't start",
    "created_at": "2024-09-19T19:50:44Z",
    "closed_at": "2024-09-20T00:45:15Z",
    "labels": [],
    "url": "https://github.com/cocktailpeanut/fluxgym/issues/112",
    "body": "Getting the following error with a fresh install (code as of 19 Sept):\r\n\r\nTraceback (most recent call last):\r\n  File \"app.py\", line 19, in <module>\r\n    from library import flux_train_utils, huggingface_util\r\n  File \"/home/test/fluxgym/sd-scripts/library/flux_train_utils.py\", line 17, in <module>\r\n    from library import flux_models, flux_utils, strategy_base, train_util\r\n  File \"/home/test/fluxgym/sd-scripts/library/flux_models.py\", line 22, in <module>\r\n    class FluxParams:\r\n  File \"/home/test/fluxgym/sd-scripts/library/flux_models.py\", line 31, in FluxParams\r\n    axes_dim: list[int]\r\nTypeError: 'type' object is not subscriptable",
    "comments_url": "https://api.github.com/repos/cocktailpeanut/fluxgym/issues/112/comments",
    "author": "palvarez19",
    "comments": [
      {
        "user": "6Morpheus6",
        "created_at": "2024-09-19T20:53:33Z",
        "body": "@palvarez19\r\nDo you get it when you try to start Flux?\r\nI installed it as well a few hours ago. It was starting on Windows 10.\r\nAlso please check if the unet model is present in `./fluxgym/models/unet`\r\nthe 2 clip models are in `./fluxgym/models/clip`\r\nand the vae model is in `./fluxgym/models/vae`"
      },
      {
        "user": "palvarez19",
        "created_at": "2024-09-20T00:43:11Z",
        "body": "> @palvarez19 Do you get it when you try to start Flux? I installed it as well a few hours ago. It was starting on Windows 10. Also please check if the unet model is present in `./fluxgym/models/unet` the 2 clip models are in `./fluxgym/models/clip` and the vae model is in `./fluxgym/models/vae`\r\n\r\nYes, I doubled checked and all the files are in the right directories."
      },
      {
        "user": "palvarez19",
        "created_at": "2024-09-20T00:45:15Z",
        "body": "I reinstalled everything again, but specifying python3.10, like this: python3.10 -m venv env. Fluxgym ran after doing that."
      }
    ]
  },
  {
    "number": 102,
    "title": "Apply environ and path changes before other imports",
    "created_at": "2024-09-17T11:11:35Z",
    "closed_at": "2024-09-17T12:52:46Z",
    "labels": [],
    "url": "https://github.com/cocktailpeanut/fluxgym/pull/102",
    "body": "In `python 3.12` you need to modify the paths before the import happens or else the execution will fail complaining with the error `ModuleNotFoundError: No module named 'train_network'`, as referenced in issue #101 \r\n\r\nIn this PR I moved the environ and path changes to right after the `os` and `sys` imports. This makes the app launch successfully in `python 3.12`",
    "comments_url": "https://api.github.com/repos/cocktailpeanut/fluxgym/issues/102/comments",
    "author": "diego-treitos",
    "comments": [
      {
        "user": "cocktailpeanut",
        "created_at": "2024-09-17T12:52:49Z",
        "body": "Thank you, My bad!"
      }
    ]
  },
  {
    "number": 97,
    "title": "Wait for the author to update it, it doesn't work after yesterday's modification.",
    "created_at": "2024-09-17T02:58:25Z",
    "closed_at": "2024-09-17T07:59:34Z",
    "labels": [],
    "url": "https://github.com/cocktailpeanut/fluxgym/issues/97",
    "body": "Traceback (most recent call last):\r\n  File \"D:\\fluxgym\\app.py\", line 17, in <module>\r\n    import train_network\r\nModuleNotFoundError: No module named 'train_network'",
    "comments_url": "https://api.github.com/repos/cocktailpeanut/fluxgym/issues/97/comments",
    "author": "wuliang19869312",
    "comments": [
      {
        "user": "Tablaski",
        "created_at": "2024-09-17T07:07:34Z",
        "body": "I've had the same issue. I've solved it by copying fluxgym\\sd-scripts\\training_network.py into the root folder fluxgym\r\n"
      }
    ]
  },
  {
    "number": 94,
    "title": "ModuleNotFoundError: No module named 'train_network'",
    "created_at": "2024-09-16T23:33:48Z",
    "closed_at": "2024-09-18T10:04:06Z",
    "labels": [],
    "url": "https://github.com/cocktailpeanut/fluxgym/issues/94",
    "body": "When running `python app.py` after completing manual install steps this error shows. No clue how to resolve, any help would be appreciated\r\n\r\n`ModuleNotFoundError: No module named 'train_network'`",
    "comments_url": "https://api.github.com/repos/cocktailpeanut/fluxgym/issues/94/comments",
    "author": "keizured",
    "comments": [
      {
        "user": "scooper86",
        "created_at": "2024-09-17T00:59:42Z",
        "body": "Same issue for me, installed via git on windows "
      },
      {
        "user": "wuliang19869312",
        "created_at": "2024-09-17T02:20:12Z",
        "body": "Traceback (most recent call last):\r\n  File \"D:\\fluxgym\\app.py\", line 17, in <module>\r\n    import train_network\r\nModuleNotFoundError: No module named 'train_network'\r\nwhy???"
      },
      {
        "user": "one-pip",
        "created_at": "2024-09-17T03:07:05Z",
        "body": "yes, i git pull today , then met this problem"
      },
      {
        "user": "deepfriedheroin",
        "created_at": "2024-09-17T04:04:09Z",
        "body": "I'm sure there's better way to do this, but here. \r\n```\r\nsys.path.append(os.path.abspath('./sd-scripts'))\r\nimport train_network\r\n```"
      },
      {
        "user": "vizuelvfx",
        "created_at": "2024-09-17T11:22:40Z",
        "body": "Wow, thank you!!! that helped me, I didn't know what to do either."
      },
      {
        "user": "one-pip",
        "created_at": "2024-09-17T12:30:09Z",
        "body": "> I'm sure there's better way to do this, but here.\r\n> \r\n> ```\r\n> sys.path.append(os.path.abspath('./sd-scripts'))\r\n> import train_network\r\n> ```\r\n\r\nthanks, i made it"
      },
      {
        "user": "chnisar515",
        "created_at": "2024-09-17T17:55:17Z",
        "body": "i am facing the same error\r\n\r\n> (env) E:\\fluxgym>python app.py\r\nTraceback (most recent call last):\r\n  File \"E:\\fluxgym\\app.py\", line 17, in <module>\r\n    import train_network\r\nModuleNotFoundError: No module named 'train_network'\r\n\r\ncan someone tell me how i can fix this?\r\ni replaced these lines in my app.py file\r\nnow my app.py files looks like below\r\n\r\n> import os\r\nimport sys\r\nimport subprocess\r\nimport gradio as gr\r\nfrom PIL import Image\r\nimport torch\r\nimport uuid\r\nimport shutil\r\nimport json\r\nimport yaml\r\nfrom slugify import slugify\r\nfrom transformers import AutoProcessor, AutoModelForCausalLM\r\nfrom gradio_logsview import LogsView, LogsViewRunner\r\nfrom huggingface_hub import hf_hub_download, HfApi\r\nfrom library import flux_train_utils, huggingface_util\r\nfrom argparse import Namespace\r\nimport train_network\r\nimport toml\r\nimport re\r\nos.environ[\"HF_HUB_ENABLE_HF_TRANSFER\"] = \"1\"\r\nos.environ['GRADIO_ANALYTICS_ENABLED'] = '0'\r\nsys.path.insert(0, os.getcwd())\r\nsys.path.append(os.path.abspath('./sd-scripts'))\r\nimport train_network\r\nMAX_IMAGES = 150"
      },
      {
        "user": "keizured",
        "created_at": "2024-09-18T10:04:06Z",
        "body": "Issue was resolved with latest commit, thank you for fix!"
      }
    ]
  },
  {
    "number": 42,
    "title": "UserWarning: cuDNN SDPA backward got grad_output.stride",
    "created_at": "2024-09-10T01:25:55Z",
    "closed_at": "2024-09-13T13:15:43Z",
    "labels": [],
    "url": "https://github.com/cocktailpeanut/fluxgym/issues/42",
    "body": "[2024-09-10 09:23:21] [INFO] epoch 1/16\r\n[2024-09-10 09:23:29] [INFO] 2024-09-10 09:23:29 INFO     epoch is incremented.            train_util.py:668\r\n[2024-09-10 09:23:29] [INFO] current_epoch: 0, epoch: 1\r\n[2024-09-10 09:23:29] [INFO] 2024-09-10 09:23:29 INFO     epoch is incremented.            train_util.py:668\r\n[2024-09-10 09:23:29] [INFO] current_epoch: 0, epoch: 1\r\n[2024-09-10 09:23:37] [INFO] C:\\AI\\fluxgym\\env\\Lib\\site-packages\\torch\\autograd\\graph.py:825: UserWarning: cuDNN SDPA backward got grad_output.strides() != output.strides(), attempting to materialize a grad_output with matching strides... (Triggered internally at C:\\actions-runner\\_work\\pytorch\\pytorch\\builder\\windows\\pytorch\\aten\\src\\ATen\\native\\cudnn\\MHA.cpp:672.)\r\n[2024-09-10 09:23:37] [INFO] return Variable._execution_engine.run_backward(  # Calls into the C++ engine to run the backward pass\r\n\r\nwhat is this problem with that?  i just loaded 8 pictures with this problem, but i loaded fewer pictures, as 5,  it is ok for trainning.",
    "comments_url": "https://api.github.com/repos/cocktailpeanut/fluxgym/issues/42/comments",
    "author": "one-pip",
    "comments": [
      {
        "user": "legionario98",
        "created_at": "2024-09-10T02:14:24Z",
        "body": "Same error here, some solution ?"
      },
      {
        "user": "chubbypillow93",
        "created_at": "2024-09-10T02:19:17Z",
        "body": "Same problem here :("
      },
      {
        "user": "ronbere",
        "created_at": "2024-09-10T08:57:55Z",
        "body": "same..."
      },
      {
        "user": "bigfordy1983",
        "created_at": "2024-09-10T12:48:21Z",
        "body": "same... Although GPU is still spooled up and processing."
      },
      {
        "user": "gohan2091",
        "created_at": "2024-09-10T17:23:14Z",
        "body": "Same error! it doesn't progress forward either\r\n\r\n[2024-09-10 18:09:50] [INFO] 2024-09-10 18:09:50 INFO     move t5XXL back to cpu   flux_train_network.py:256\r\n[2024-09-10 18:09:54] [INFO] 2024-09-10 18:09:54 INFO     move vae and unet back   flux_train_network.py:261\r\n[2024-09-10 18:09:54] [INFO] to original device\r\n[2024-09-10 18:09:54] [INFO] INFO     create LoRA network. base dim     lora_flux.py:484\r\n[2024-09-10 18:09:54] [INFO] (rank): 4, alpha: 1\r\n[2024-09-10 18:09:54] [INFO] INFO     neuron dropout: p=None, rank      lora_flux.py:485\r\n[2024-09-10 18:09:54] [INFO] dropout: p=None, module dropout:\r\n[2024-09-10 18:09:54] [INFO] p=None\r\n[2024-09-10 18:09:54] [INFO] INFO     train all blocks only             lora_flux.py:495\r\n[2024-09-10 18:09:54] [INFO] INFO     create LoRA for Text Encoder 1:   lora_flux.py:576\r\n[2024-09-10 18:09:54] [INFO] INFO     create LoRA for Text Encoder 1:   lora_flux.py:579\r\n[2024-09-10 18:09:54] [INFO] 72 modules.\r\n[2024-09-10 18:09:54] [INFO] INFO     create LoRA for FLUX all blocks:  lora_flux.py:593\r\n[2024-09-10 18:09:54] [INFO] 304 modules.\r\n[2024-09-10 18:09:54] [INFO] INFO     enable LoRA for text encoder: 72  lora_flux.py:736\r\n[2024-09-10 18:09:54] [INFO] modules\r\n[2024-09-10 18:09:54] [INFO] INFO     enable LoRA for U-Net: 304        lora_flux.py:741\r\n[2024-09-10 18:09:54] [INFO] modules\r\n[2024-09-10 18:09:54] [INFO] FLUX: Gradient checkpointing enabled. CPU offload: False\r\n[2024-09-10 18:09:54] [INFO] prepare optimizer, data loader etc.\r\n[2024-09-10 18:09:54] [INFO] INFO     Text Encoder 1 (CLIP-L): 72       lora_flux.py:840\r\n[2024-09-10 18:09:54] [INFO] modules, LR 0.0008\r\n[2024-09-10 18:09:54] [INFO] INFO     use 8-bit AdamW optimizer | {}  train_util.py:4343\r\n[2024-09-10 18:09:54] [INFO] override steps. steps for 10 epochs is / 指定エポックまでのステップ数: 5500\r\n[2024-09-10 18:09:54] [INFO] enable fp8 training for U-Net.\r\n[2024-09-10 18:09:54] [INFO] enable fp8 training for Text Encoder.\r\n[2024-09-10 18:10:52] [INFO] 2024-09-10 18:10:52 INFO     prepare CLIP-L for fp8:  flux_train_network.py:464\r\n[2024-09-10 18:10:52] [INFO] set to\r\n[2024-09-10 18:10:52] [INFO] torch.float8_e4m3fn, set\r\n[2024-09-10 18:10:52] [INFO] embeddings to\r\n[2024-09-10 18:10:52] [INFO] torch.bfloat16\r\n[2024-09-10 18:10:52] [INFO] running training / 学習開始\r\n[2024-09-10 18:10:52] [INFO] num train images * repeats / 学習画像の数×繰り返し回数: 550\r\n[2024-09-10 18:10:52] [INFO] num reg images / 正則化画像の数: 0\r\n[2024-09-10 18:10:52] [INFO] num batches per epoch / 1epochのバッチ数: 550\r\n[2024-09-10 18:10:52] [INFO] num epochs / epoch数: 10\r\n[2024-09-10 18:10:52] [INFO] batch size per device / バッチサイズ: 1\r\n[2024-09-10 18:10:52] [INFO] gradient accumulation steps / 勾配を合計するステップ数 = 1\r\n[2024-09-10 18:10:52] [INFO] total optimization steps / 学習ステップ数: 5500\r\n[2024-09-10 18:11:10] [INFO] steps:   0%|          | 0/5500 [00:00<?, ?it/s]2024-09-10 18:11:10 INFO     unet dtype:                  train_network.py:1050\r\n[2024-09-10 18:11:10] [INFO] torch.float8_e4m3fn, device:\r\n[2024-09-10 18:11:10] [INFO] cuda:0\r\n[2024-09-10 18:11:10] [INFO] INFO     text_encoder [0] dtype:      train_network.py:1056\r\n[2024-09-10 18:11:10] [INFO] torch.float8_e4m3fn, device:\r\n[2024-09-10 18:11:10] [INFO] cuda:0\r\n[2024-09-10 18:11:10] [INFO] INFO     text_encoder [1] dtype:      train_network.py:1056\r\n[2024-09-10 18:11:10] [INFO] torch.bfloat16, device: cpu\r\n[2024-09-10 18:11:10] [INFO] \r\n[2024-09-10 18:11:10] [INFO] epoch 1/10\r\n[2024-09-10 18:11:18] [INFO] 2024-09-10 18:11:18 INFO     epoch is incremented.            train_util.py:668\r\n[2024-09-10 18:11:18] [INFO] current_epoch: 0, epoch: 1\r\n[2024-09-10 18:11:18] [INFO] 2024-09-10 18:11:18 INFO     epoch is incremented.            train_util.py:668\r\n[2024-09-10 18:11:18] [INFO] current_epoch: 0, epoch: 1\r\n[2024-09-10 18:11:23] [INFO] C:\\Users\\USER\\AI\\fluxgym\\env\\Lib\\site-packages\\torch\\autograd\\graph.py:825: UserWarning: cuDNN SDPA backward got grad_output.strides() != output.strides(), attempting to materialize a grad_output with matching strides... (Triggered internally at C:\\actions-runner\\_work\\pytorch\\pytorch\\builder\\windows\\pytorch\\aten\\src\\ATen\\native\\cudnn\\MHA.cpp:672.)\r\n[2024-09-10 18:11:23] [INFO] return Variable._execution_engine.run_backward(  # Calls into the C++ engine to run the backward pass"
      },
      {
        "user": "tman1015",
        "created_at": "2024-09-10T17:37:26Z",
        "body": "Also getting the same error before getting avr_loss=nan for every single epoch. It's very frustrating."
      },
      {
        "user": "one-pip",
        "created_at": "2024-09-11T09:25:37Z",
        "body": "it may be not a problem, just wait for a while, it will start to train "
      },
      {
        "user": "ronbere",
        "created_at": "2024-09-11T15:08:07Z",
        "body": "> it may be not a problem, just wait for a while, it will start to train\r\n\r\nIts a problem...Not working\r\n"
      },
      {
        "user": "bigfordy1983",
        "created_at": "2024-09-11T15:38:27Z",
        "body": "@ronbere, I thought the same but mine is working. Under task manager, what is the GPU memory usage saying?"
      },
      {
        "user": "gohan2091",
        "created_at": "2024-09-12T22:09:15Z",
        "body": "> @ronbere, I thought the same but mine is working. Under task manager, what is the GPU memory usage saying?\r\n\r\nMine appears to be doing something with the GPU after this error but FluxGym does not tell me the estimated time of completion. I've had it running now for over 30 minutes and the last entry in the console was 30 minutes ago with that error. I've no idea how long this will take or if it's even doing anything productive or just using my GPU constantly because it's stuck.\r\n\r\nEDIT: ok epoch 2 has kicked in. At least I can see the console is active."
      },
      {
        "user": "ronbere",
        "created_at": "2024-09-13T17:52:09Z",
        "body": "> @ronbere, I thought the same but mine is working. Under task manager, what is the GPU memory usage saying?\n\nGPU usage 27%"
      },
      {
        "user": "AndrewDrimer",
        "created_at": "2024-09-15T00:30:39Z",
        "body": "some problem starting after 25 min. very slow. update this"
      }
    ]
  },
  {
    "number": 37,
    "title": "Command exited with code 1",
    "created_at": "2024-09-09T13:41:03Z",
    "closed_at": "2024-09-10T18:09:03Z",
    "labels": [],
    "url": "https://github.com/cocktailpeanut/fluxgym/issues/37",
    "body": "Maybe because it`s forced to use bf16 which is not supported by rtx20xx arch cards?\r\nI have 16gb ram and 12gb vram and 1/2 of Quadro 6000(Turing Generation)\r\n\r\n[2024-09-09 13:36:15] [INFO] Traceback (most recent call last):\r\n[2024-09-09 13:36:15] [INFO] File \"D:\\pinokio\\bin\\miniconda\\lib\\runpy.py\", line 196, in _run_module_as_main\r\n[2024-09-09 13:36:15] [INFO] return _run_code(code, main_globals, None,\r\n[2024-09-09 13:36:15] [INFO] File \"D:\\pinokio\\bin\\miniconda\\lib\\runpy.py\", line 86, in _run_code\r\n[2024-09-09 13:36:15] [INFO] exec(code, run_globals)\r\n[2024-09-09 13:36:15] [INFO] File \"D:\\pinokio\\api\\fluxgym.git\\env\\Scripts\\accelerate.exe\\__main__.py\", line 7, in <module>\r\n[2024-09-09 13:36:15] [INFO] File \"D:\\pinokio\\api\\fluxgym.git\\env\\lib\\site-packages\\accelerate\\commands\\accelerate_cli.py\", line 48, in main\r\n[2024-09-09 13:36:15] [INFO] args.func(args)\r\n[2024-09-09 13:36:15] [INFO] File \"D:\\pinokio\\api\\fluxgym.git\\env\\lib\\site-packages\\accelerate\\commands\\launch.py\", line 1106, in launch_command\r\n[2024-09-09 13:36:15] [INFO] simple_launcher(args)\r\n[2024-09-09 13:36:15] [INFO] File \"D:\\pinokio\\api\\fluxgym.git\\env\\lib\\site-packages\\accelerate\\commands\\launch.py\", line 704, in simple_launcher\r\n[2024-09-09 13:36:15] [INFO] raise subprocess.CalledProcessError(returncode=process.returncode, cmd=cmd)\r\n[2024-09-09 13:36:15] [INFO] subprocess.CalledProcessError: Command '['D:\\\\pinokio\\\\api\\\\fluxgym.git\\\\env\\\\Scripts\\\\python.exe', 'sd-scripts/flux_train_network.py', '--pretrained_model_name_or_path', 'D:\\\\pinokio\\\\api\\\\fluxgym.git\\\\models\\\\unet\\\\flux1-dev.sft', '--clip_l', 'D:\\\\pinokio\\\\api\\\\fluxgym.git\\\\models\\\\clip\\\\clip_l.safetensors', '--t5xxl', 'D:\\\\pinokio\\\\api\\\\fluxgym.git\\\\models\\\\clip\\\\t5xxl_fp16.safetensors', '--ae', 'D:\\\\pinokio\\\\api\\\\fluxgym.git\\\\models\\\\vae\\\\ae.sft', '--cache_latents_to_disk', '--save_model_as', 'safetensors', '--sdpa', '--persistent_data_loader_workers', '--max_data_loader_n_workers', '2', '--seed', '42', '--gradient_checkpointing', '--mixed_precision', 'bf16', '--save_precision', 'bf16', '--network_module', 'networks.lora_flux', '--network_dim', '4', '--optimizer_type', 'adafactor', '--optimizer_args', 'relative_step=False', 'scale_parameter=False', 'warmup_init=False', '--split_mode', '--network_args', 'train_blocks=single', '--lr_scheduler', 'constant_with_warmup', '--max_grad_norm', '0.0', '--learning_rate', '8e-4', '--cache_text_encoder_outputs', '--cache_text_encoder_outputs_to_disk', '--fp8_base', '--highvram', '--max_train_epochs', '16', '--save_every_n_epochs', '4', '--dataset_config', 'D:\\\\pinokio\\\\api\\\\fluxgym.git\\\\dataset.toml', '--output_dir', 'D:\\\\pinokio\\\\api\\\\fluxgym.git\\\\outputs', '--output_name', 'natalyn', '--timestep_sampling', 'shift', '--discrete_flow_shift', '3.1582', '--model_prediction_type', 'raw', '--guidance_scale', '1', '--loss_type', 'l2']' returned non-zero exit status 3221225477.\r\n[2024-09-09 13:36:16] [ERROR] Command exited with code 1\r\n[2024-09-09 13:36:16] [INFO] Runner: <LogsViewRunner nb_logs=107 exit_code=1>",
    "comments_url": "https://api.github.com/repos/cocktailpeanut/fluxgym/issues/37/comments",
    "author": "Telllinex",
    "comments": [
      {
        "user": "richiepic",
        "created_at": "2024-09-10T13:06:08Z",
        "body": "Same here"
      },
      {
        "user": "Telllinex",
        "created_at": "2024-09-10T13:31:31Z",
        "body": "Idk if author of fluxgym can really do anything about this error, i tried kohyass gui and the same error occurs…. \r\nI saw a lot of people complaining about kohyass broken repo with a lot of issues that only lucky ones can run it without issues :)"
      },
      {
        "user": "richiepic",
        "created_at": "2024-09-10T13:35:21Z",
        "body": "In previous comment I've seen there is a problem with pinokio install only.  Now I'm updating, but takes ages. It downloads the whole internet. 206 GB so far. ????"
      },
      {
        "user": "Telllinex",
        "created_at": "2024-09-10T18:09:03Z",
        "body": "> In previous comment I've seen there is a problem with pinokio install only. Now I'm updating, but takes ages. It downloads the whole internet. 206 GB so far. ????\r\n\r\nI rage deleted both kohya_ss and fluxgym and now successfully training in onetrainer without any issue on 12gb vram)\r\nI guess both kohya and fluxgym is so fragile to a lot of aspects it is not worth waiting for help and waisting time to install and fix everything)"
      }
    ]
  },
  {
    "number": 2,
    "title": "do we need to use Q8 gguf for 12gb gpu ? ",
    "created_at": "2024-09-06T18:53:43Z",
    "closed_at": "2024-10-16T10:53:46Z",
    "labels": [],
    "url": "https://github.com/cocktailpeanut/fluxgym/issues/2",
    "body": null,
    "comments_url": "https://api.github.com/repos/cocktailpeanut/fluxgym/issues/2/comments",
    "author": "l33tx0",
    "comments": [
      {
        "user": "BlastedRemnants",
        "created_at": "2024-09-11T19:05:55Z",
        "body": "No, I've trained 3 Loras so far with this tool on my 12 GB card, with 1024x1024 source pics, and without needing to change the model."
      }
    ]
  }
]